tests/64_threads/sample_2.in
64
o
63 S 101 7 136 364
15 B 102 6 101 497
15 C 102
59 S 104 2 146 607
38 S 105 5 159 470
36 S 106 7 153 16
11 B 108 0 112 260
26 S 109 9 190 740
52 S 110 6 113 373
30 S 111 0 151 733
21 B 112 0 144 574
59 S 115 6 158 540
42 B 116 0 157 503
5 B 118 9 140 914
49 B 119 6 129 326
54 B 120 3 132 373
13 S 121 2 158 344
11 B 122 5 141 898
20 B 123 3 167 865
0 B 124 9 197 218
23 S 125 0 167 436
20 B 126 7 169 945
43 B 128 6 107 185
55 B 129 5 107 586
19 S 130 3 120 751
1 S 131 9 134 840
7 B 132 4 156 748
8 S 133 9 132 59
8 C 133
35 B 135 0 103 47
59 S 137 8 156 483
58 S 138 8 186 62
7 B 140 7 148 37
52 C 110
63 C 101
57 S 143 4 144 523
2 S 144 5 134 314
59 B 145 0 157 995
24 S 147 2 161 478
27 S 148 7 118 198
0 S 149 4 103 867
13 S 151 3 109 720
17 S 154 4 163 211
10 B 155 6 186 446
2 C 144
54 S 157 9 175 449
5 S 158 6 125 853
7 S 160 4 151 445
42 C 116
15 B 163 9 130 892
24 B 164 0 171 852
24 B 165 8 124 123
43 C 128
50 B 167 1 184 436
1 C 131
46 B 169 5 156 629
10 C 155
44 B 172 8 192 276
36 C 106
15 S 174 5 115 389
20 S 175 6 195 656
38 S 176 6 137 589
17 C 154
30 C 111
50 B 179 9 176 281
57 C 143
45 B 182 4 146 555
55 S 183 6 152 891
16 S 184 9 154 347
4 S 185 0 194 849
9 S 186 0 143 686
1 B 187 0 107 486
58 C 138
62 B 189 8 153 503
42 C 116
8 C 133
10 C 155
44 B 193 6 192 618
46 C 169
31 S 196 1 192 808
7 B 200 9 152 801
50 S 201 4 100 36
26 C 109
11 B 203 9 101 240
63 S 204 6 133 109
38 S 206 6 138 694
19 B 207 3 168 115
33 B 210 7 143 327
20 C 175
23 C 125
33 C 210
58 C 138
30 S 217 7 155 476
52 B 218 7 124 456
3 B 219 3 101 825
41 B 220 4 134 543
20 S 221 5 116 802
28 B 222 7 142 645
57 B 225 8 122 356
15 B 226 5 119 534
17 B 227 5 154 732
47 B 228 9 107 754
10 C 155
7 S 230 0 117 259
9 C 186
28 S 233 2 147 541
58 B 234 3 120 343
41 B 235 1 172 92
42 B 236 8 198 863
56 B 237 2 192 873
34 S 239 3 148 451
44 S 240 4 105 862
52 S 241 0 121 850
60 B 242 7 103 956
34 S 243 9 150 518
40 B 244 3 107 474
22 B 245 0 181 625
47 S 246 6 127 811
29 S 247 8 130 617
26 B 248 2 126 867
26 S 249 9 188 68
46 S 250 0 198 367
41 S 251 3 121 850
10 B 253 5 159 802
5 S 254 3 133 803
44 S 255 7 111 214
44 C 193
6 S 257 4 123 416
0 C 149
51 B 259 2 131 641
57 B 260 2 120 630
6 B 261 9 163 550
16 B 262 1 149 477
63 C 101
57 B 264 4 134 13
47 C 228
27 B 267 7 152 882
4 B 268 2 179 325
26 C 248
9 C 186
15 S 271 9 126 458
3 B 272 7 191 464
33 S 273 1 148 144
27 B 274 2 197 88
16 C 184
36 B 276 6 135 645
51 C 259
46 C 250
59 B 279 3 120 628
61 S 280 0 180 467
3 S 281 3 111 908
45 S 282 2 114 258
27 S 283 3 132 712
46 B 284 3 119 679
35 B 285 2 116 887
53 B 286 4 125 529
13 B 287 5 147 597
46 B 288 1 132 809
27 B 289 1 176 902
21 B 290 1 160 502
17 C 154
57 B 292 3 157 311
19 S 293 9 140 71
33 S 294 6 100 798
15 C 271
7 S 296 4 142 747
63 S 297 9 174 649
57 C 143
0 C 149
5 S 300 6 130 248
22 S 301 1 167 296
53 C 286
41 S 303 5 120 440
9 S 304 2 134 527
43 C 128
0 C 149
43 S 307 0 135 488
20 B 308 5 165 989
59 S 309 7 155 506
17 S 310 5 162 302
40 S 311 3 106 761
51 C 259
29 C 247
4 C 268
13 C 121
20 C 175
38 C 105
4 S 319 6 113 180
52 C 218
12 B 321 0 194 462
14 S 322 5 177 600
50 S 323 3 199 573
22 B 324 6 183 556
24 C 147
53 C 286
50 C 323
53 C 286
62 S 329 2 163 355
60 B 330 8 189 967
21 B 331 0 151 475
2 B 332 5 124 743
9 C 186
47 B 334 2 147 934
63 B 335 8 153 830
45 B 336 3 193 256
56 S 337 2 158 411
52 C 241
40 B 339 9 121 13
34 C 239
19 S 341 8 156 105
11 C 108
29 B 343 4 146 621
50 S 344 7 132 630
5 C 118
10 S 346 6 112 632
35 S 347 5 104 172
47 S 348 3 162 927
13 B 349 8 119 620
4 S 351 6 155 430
32 B 352 0 147 249
11 S 353 5 148 213
36 S 354 3 198 895
41 B 355 2 136 310
34 S 356 0 124 535
13 S 357 3 106 678
63 B 358 9 170 205
38 S 359 5 103 483
5 C 118
42 S 361 1 160 653
29 C 247
49 S 363 2 127 623
63 C 297
17 C 227
51 S 366 3 182 117
2 S 367 0 198 302
54 S 368 6 123 170
41 S 369 9 199 429
20 B 370 9 198 579
17 S 371 4 190 222
40 S 372 3 187 312
36 S 373 6 140 676
41 C 369
50 C 201
16 S 376 6 130 700
6 S 377 5 133 321
59 B 378 1 100 720
38 B 380 9 154 961
2 B 381 2 133 743
62 S 382 0 122 342
56 C 237
27 S 384 7 105 812
50 C 167
19 B 387 6 112 500
3 C 281
41 C 235
14 B 390 5 143 481
48 S 391 4 183 946
12 C 321
60 B 393 4 145 672
30 B 394 8 110 412
49 B 395 0 182 885
48 S 396 6 166 845
54 S 397 8 111 344
30 C 394
31 S 399 5 170 552
51 S 400 5 129 819
44 B 401 4 168 960
35 S 402 0 116 216
8 S 403 8 159 557
18 B 404 9 110 791
6 S 405 5 185 382
37 B 406 3 162 245
44 B 407 1 190 214
59 B 408 9 100 330
63 C 358
27 B 410 8 150 518
40 B 411 7 134 963
60 C 393
56 S 413 7 192 929
53 B 414 8 164 471
35 C 285
31 C 196
53 C 286
58 S 418 1 190 68
58 C 418
32 S 420 5 130 949
52 S 421 8 107 680
54 B 422 6 131 386
45 S 423 9 190 958
22 B 424 6 158 61
29 B 425 7 114 531
55 S 426 9 177 974
32 S 427 3 160 664
23 S 428 2 164 796
50 S 429 0 114 150
25 B 430 0 119 291
59 S 431 9 126 570
22 S 432 0 199 306
57 B 433 7 168 92
57 B 434 5 104 415
1 C 131
0 S 436 3 119 543
60 B 437 0 187 291
29 S 438 8 113 590
15 B 439 6 120 514
48 C 396
9 S 441 7 118 761
56 S 442 5 191 27
62 S 443 9 164 162
30 B 444 6 148 787
10 S 445 8 187 793
3 S 446 8 106 143
37 S 447 8 168 985
6 B 448 4 171 848
35 B 449 6 192 557
32 S 450 8 126 543
53 B 451 8 195 592
38 B 452 0 183 755
59 B 453 9 177 395
61 S 454 4 192 963
62 C 382
24 C 164
34 C 243
33 C 294
5 B 459 8 138 666
23 B 460 0 162 250
34 S 461 8 102 89
56 B 462 4 114 33
37 B 463 3 187 287
22 C 432
41 C 251
5 S 466 2 100 46
2 B 467 2 131 620
47 S 468 2 129 606
46 S 469 9 175 616
30 C 394
16 B 471 8 136 288
28 C 222
4 B 473 7 154 619
23 B 474 7 181 67
62 C 189
62 B 476 1 168 519
3 C 219
44 C 193
37 S 479 8 123 80
52 C 218
41 B 481 5 193 687
36 C 354
19 C 387
50 B 484 0 159 642
50 B 485 0 151 618
48 B 486 2 151 655
53 C 451
7 S 488 7 101 436
37 C 406
40 C 339
20 C 175
35 B 492 4 137 772
53 B 493 5 175 572
14 S 494 3 176 408
11 B 495 2 111 560
33 S 496 9 145 143
54 S 497 6 127 123
10 S 498 9 129 882
3 B 499 1 141 719
40 C 411
34 C 461
19 B 502 0 105 342
2 S 503 5 169 348
13 B 504 9 172 976
21 S 505 1 130 742
52 B 506 2 111 431
3 B 507 4 123 803
13 C 349
55 S 509 6 180 19
46 C 284
21 S 511 0 130 360
0 S 512 5 176 64
16 S 513 8 148 1000
24 B 514 7 195 561
4 B 515 8 117 494
34 B 516 8 193 517
35 B 517 5 160 713
37 S 518 8 159 956
42 B 519 9 109 985
48 S 520 8 149 898
59 S 521 7 141 972
51 C 400
25 S 523 0 157 314
27 C 274
55 B 525 5 164 216
27 S 526 0 153 928
38 B 527 5 188 547
8 B 528 4 156 451
38 B 529 2 175 567
15 C 174
18 B 531 0 143 118
24 C 147
7 B 533 3 182 642
47 S 534 8 198 994
15 S 535 9 190 793
7 C 230
43 B 537 3 170 36
12 S 538 9 155 329
7 C 296
32 S 540 3 166 402
44 S 541 5 195 685
51 S 542 1 126 254
22 S 543 7 192 345
37 C 518
42 C 361
48 B 546 9 134 684
2 S 547 3 199 702
26 C 109
30 C 394
43 S 550 2 176 332
47 S 551 7 123 958
9 C 441
46 C 288
16 B 554 2 144 756
4 C 319
21 S 556 2 178 47
36 B 557 6 130 17
52 C 241
13 S 559 7 170 506
53 C 414
54 B 561 6 138 563
34 S 562 6 134 734
50 C 323
54 C 120
48 B 565 0 175 640
49 S 566 4 182 697
24 S 567 5 102 700
39 S 568 8 192 850
7 B 569 8 163 528
51 S 570 9 190 205
21 S 571 4 125 911
21 C 290
25 S 573 8 105 636
33 C 496
51 C 259
48 C 391
24 C 147
40 S 578 8 175 184
53 S 579 1 187 14
46 C 284
20 B 581 2 112 604
4 B 582 1 174 533
7 S 583 3 156 444
46 B 584 0 197 164
26 S 585 0 190 380
50 C 484
47 B 587 4 181 93
59 B 588 3 139 985
9 C 186
0 B 590 4 144 897
47 S 591 1 148 215
39 C 568
45 C 282
23 B 594 3 135 513
35 S 595 5 121 595
9 B 596 8 160 131
54 B 597 4 164 499
56 S 598 0 119 687
25 B 599 7 125 986
16 S 600 2 149 550
53 C 493
52 S 602 5 177 160
21 S 603 1 168 547
4 S 604 0 197 118
42 B 605 1 144 911
18 S 606 3 126 12
16 S 607 1 108 170
10 B 608 7 100 995
59 B 609 2 122 343
13 C 504
30 C 217
22 S 612 3 189 916
57 S 613 1 186 647
10 B 614 3 158 770
60 B 615 4 147 650
50 B 616 2 133 174
22 C 424
41 S 618 5 117 78
22 S 619 9 190 210
58 C 138
60 B 621 2 108 177
37 S 622 6 123 645
10 B 623 6 103 557
30 C 111
48 B 625 9 170 648
53 B 626 4 120 812
2 C 503
17 S 628 8 188 164
25 C 573
61 B 630 9 107 912
48 C 565
45 B 632 9 167 82
