tests/64_threads/sample_20.in
64
o
42 B 101 5 118 511
33 B 102 7 170 469
27 B 106 0 182 153
18 B 108 3 189 802
59 B 109 2 136 119
4 B 111 7 114 414
15 S 112 9 143 329
50 B 113 2 179 251
2 B 114 3 148 375
53 B 116 3 167 833
34 S 122 8 121 749
1 S 123 7 199 981
45 S 124 6 191 490
38 B 126 2 186 22
21 S 127 0 132 510
44 B 129 5 169 319
59 C 109
3 B 132 5 167 648
53 B 133 6 180 846
2 B 134 8 143 573
33 C 102
42 S 136 6 163 636
52 S 137 7 183 230
48 S 139 6 124 170
49 B 140 2 193 380
2 B 141 6 173 584
56 S 142 0 153 384
0 B 144 7 156 749
7 B 145 0 149 68
44 S 146 4 197 348
22 B 147 3 100 238
59 B 148 7 127 584
32 B 149 2 160 951
33 S 150 5 111 195
56 S 151 0 119 641
6 S 152 6 114 198
50 B 153 2 186 542
13 S 155 6 156 623
37 B 156 1 136 521
58 S 157 1 181 381
43 B 158 5 182 108
12 S 160 3 175 353
41 B 161 8 109 606
60 B 162 3 196 158
48 S 163 6 157 697
7 B 164 7 106 428
45 S 165 7 124 12
41 C 161
26 B 167 9 197 183
48 S 168 7 196 328
22 C 147
14 B 171 6 111 492
37 B 172 4 149 776
29 B 173 2 164 871
52 B 174 1 173 507
28 B 176 5 194 369
32 C 149
11 B 178 0 189 506
44 S 179 1 132 704
44 C 146
61 B 181 7 185 959
6 S 182 3 187 180
59 B 183 3 195 924
5 B 185 0 112 446
44 S 186 1 164 408
49 C 140
61 S 188 5 106 716
4 C 111
25 B 190 6 100 247
1 B 191 6 157 633
46 S 192 1 135 274
33 C 102
18 B 194 0 113 443
38 C 126
35 S 196 0 147 233
33 C 102
23 S 198 6 190 870
36 B 199 5 182 40
28 S 200 4 165 185
17 S 201 0 157 225
48 C 168
13 S 203 2 131 499
15 C 112
34 C 122
29 C 173
26 C 167
23 S 208 4 100 277
16 B 210 0 171 479
28 B 212 2 100 401
32 S 213 5 157 695
49 B 214 1 134 263
44 C 129
20 B 216 3 196 477
57 S 217 6 125 280
61 S 218 3 137 448
15 C 112
54 B 220 3 191 412
30 S 221 1 114 416
17 S 222 6 101 17
57 B 223 0 192 906
47 B 224 4 180 357
36 S 225 1 137 605
32 C 213
21 S 228 4 178 17
52 S 229 1 186 800
50 C 153
14 S 231 4 192 489
53 C 133
43 S 233 1 169 185
45 B 234 6 138 690
37 S 235 8 155 750
44 S 236 0 184 274
42 B 237 4 150 693
54 B 239 0 159 691
56 C 151
51 B 241 6 195 541
6 C 152
41 S 244 4 183 188
25 C 190
51 B 246 1 123 28
12 S 247 5 176 813
45 S 249 2 135 183
33 S 250 6 141 928
20 B 251 8 186 698
1 B 252 6 126 167
10 S 253 1 164 666
7 C 145
14 S 255 9 194 738
15 B 256 9 193 181
24 B 257 5 197 204
15 C 112
14 B 260 3 113 864
61 C 218
28 B 262 7 200 555
6 S 263 0 126 388
26 B 264 2 102 666
39 S 265 4 148 18
52 S 266 2 165 935
24 S 267 5 148 439
10 C 253
25 S 269 5 118 225
13 S 270 0 119 459
29 C 173
38 C 126
37 B 273 4 110 952
14 S 274 2 160 405
57 S 275 9 171 932
25 S 276 9 122 781
20 S 277 6 149 958
21 B 278 3 157 212
54 B 279 4 184 865
15 C 256
45 S 281 7 154 359
26 C 264
22 C 147
39 S 284 2 181 195
40 S 286 6 110 679
54 C 279
37 C 273
36 B 289 5 182 721
23 S 290 0 146 43
33 C 150
23 B 292 7 137 394
20 B 293 6 196 23
35 S 294 8 127 657
15 S 295 9 117 657
28 C 176
29 C 173
35 S 298 7 130 618
21 B 299 6 164 649
51 B 300 0 111 691
63 S 301 2 154 713
6 S 302 9 118 379
1 S 303 3 165 722
61 C 188
4 B 305 9 135 128
31 S 306 0 147 988
32 C 213
49 S 308 9 198 283
45 B 309 7 200 60
9 S 310 1 165 98
58 S 311 8 104 33
63 C 301
48 C 163
23 C 208
37 B 315 6 171 871
17 B 316 2 192 872
29 S 317 4 175 581
53 S 318 3 144 337
41 S 319 5 199 354
35 B 320 5 192 103
15 C 256
35 C 298
21 B 323 3 161 79
11 S 324 3 198 307
36 S 325 6 136 106
10 C 253
28 C 212
11 S 328 8 112 495
26 B 329 1 107 379
9 S 330 2 190 366
61 B 331 0 103 440
56 B 332 8 183 751
16 C 210
62 B 334 6 127 604
1 C 191
44 S 337 2 105 836
20 B 338 4 179 585
22 S 339 5 180 665
38 S 340 3 127 615
55 B 341 0 154 542
42 S 342 4 123 318
47 C 224
4 S 344 3 169 939
40 C 286
52 B 346 1 191 531
53 C 133
59 S 348 6 105 98
6 B 349 6 154 215
48 C 163
46 B 352 2 196 352
6 S 353 1 184 939
5 B 354 3 110 380
40 B 355 9 140 91
10 S 356 8 105 740
56 S 357 9 151 841
3 S 358 2 185 644
26 S 359 2 146 340
59 S 360 6 177 496
45 C 249
31 S 362 0 173 61
8 S 363 4 108 948
27 B 364 3 151 409
50 S 365 1 102 940
36 B 366 2 185 258
12 S 367 7 128 406
60 B 368 8 108 722
36 S 369 3 185 261
44 B 370 7 130 688
0 B 371 8 104 390
24 S 372 8 145 831
25 S 373 5 168 306
1 B 374 9 120 715
41 B 375 6 176 436
26 C 264
51 C 246
10 C 253
32 B 379 4 108 621
43 C 233
6 C 263
16 B 382 0 103 133
42 S 383 0 149 948
5 B 384 3 149 682
39 B 385 6 102 164
62 S 386 1 115 629
29 S 387 9 156 850
30 S 388 3 200 403
12 B 389 5 185 551
34 C 122
62 B 391 5 152 907
54 S 392 0 122 569
30 C 388
7 B 394 0 135 860
60 C 368
35 C 196
53 C 318
2 B 398 3 186 946
29 B 399 3 125 147
55 C 341
63 C 301
46 S 402 8 151 937
62 S 403 1 147 688
55 S 404 3 116 350
53 S 405 4 124 467
35 S 406 4 124 799
14 C 260
0 C 371
8 C 363
19 S 410 6 112 884
60 C 368
46 S 412 4 181 139
52 S 413 9 188 432
31 S 414 4 122 142
27 B 415 4 113 943
43 B 416 2 167 93
22 C 147
46 B 418 2 178 241
34 S 419 5 136 709
5 C 384
41 S 421 2 168 236
14 S 422 5 176 369
7 S 423 4 133 328
31 S 424 8 121 837
24 S 425 9 159 145
1 S 426 2 122 386
41 S 427 0 114 77
31 B 428 2 178 103
55 B 429 5 187 276
44 B 430 4 186 707
38 B 431 7 181 836
24 S 432 8 148 701
22 S 433 4 151 301
53 C 116
17 C 201
6 C 182
43 S 437 8 127 190
52 B 438 4 102 660
32 C 379
0 B 440 3 151 655
23 B 441 7 171 787
12 B 442 3 133 56
41 C 421
11 S 444 9 191 453
26 B 445 5 147 365
48 S 446 0 193 22
60 C 162
38 C 340
60 S 449 4 149 106
8 S 450 3 130 242
31 C 362
11 B 452 2 146 353
20 S 453 8 160 457
9 C 310
30 S 455 3 157 344
22 S 456 3 161 390
51 S 457 3 197 412
29 B 458 0 121 358
56 C 142
23 B 460 6 180 429
42 B 461 9 195 528
34 S 462 2 153 229
11 B 463 1 103 520
63 C 301
14 S 465 7 193 959
33 C 102
7 C 145
51 C 241
43 C 158
45 C 309
51 S 471 2 168 505
40 B 472 1 179 917
39 B 473 4 179 842
57 B 474 5 149 276
36 C 225
4 B 476 4 194 407
59 B 477 9 175 442
56 B 478 1 176 501
14 S 479 5 105 228
34 S 480 0 103 277
2 B 481 6 190 992
46 S 482 1 148 348
56 S 483 1 148 81
25 B 484 5 153 99
43 C 158
51 B 486 7 161 618
32 C 213
58 B 488 7 197 879
10 S 489 4 126 873
38 C 340
34 S 491 9 149 738
8 C 363
24 B 493 1 115 322
0 B 494 1 168 751
53 B 495 3 102 559
56 S 496 4 157 366
49 C 308
22 C 433
22 S 499 7 134 399
10 S 500 8 146 968
28 B 501 1 105 280
54 C 239
0 B 503 9 132 635
56 C 332
37 B 505 8 155 618
8 C 450
11 C 452
20 S 508 4 134 337
47 C 224
7 C 394
29 C 399
50 C 365
0 C 440
7 C 145
31 C 362
19 C 410
49 B 517 4 153 115
55 C 341
6 B 519 6 120 640
22 C 456
58 C 311
5 B 522 6 101 835
4 C 344
58 C 311
21 C 127
8 C 363
0 B 527 8 113 499
53 S 528 6 113 584
56 B 529 5 187 507
2 S 530 7 128 381
12 S 531 7 172 442
47 B 532 2 133 345
25 C 269
47 C 532
56 B 535 5 188 206
18 B 536 8 123 657
23 C 290
31 S 538 7 182 646
11 B 539 4 148 933
33 C 150
5 S 541 9 160 996
60 B 542 0 117 134
47 S 543 3 198 542
2 B 544 2 112 236
14 B 545 0 115 593
11 S 546 0 182 699
58 B 547 1 143 688
29 C 399
33 S 549 9 113 405
44 S 550 3 188 933
16 B 551 6 200 894
23 B 552 0 184 466
50 B 553 5 134 937
7 B 554 8 167 849
49 S 555 4 156 857
24 C 432
36 S 557 4 154 870
60 S 558 1 162 147
13 B 559 4 135 204
45 B 560 5 137 926
4 B 561 0 157 880
17 B 562 9 100 351
9 B 563 8 130 844
63 S 564 2 132 494
41 C 421
62 S 566 2 124 546
47 C 543
52 B 568 5 117 802
30 S 569 6 186 393
63 S 570 4 155 28
46 B 571 5 174 930
56 B 572 1 198 751
51 S 573 6 176 29
17 B 574 4 198 442
17 S 575 7 185 117
23 B 576 6 194 876
31 S 577 6 152 325
3 B 578 7 119 204
12 B 579 0 140 537
29 C 317
35 B 581 1 189 394
8 S 582 6 141 553
4 S 583 8 130 238
6 S 584 9 100 369
56 C 478
53 B 586 5 141 335
21 B 587 1 137 695
9 C 310
10 B 589 3 115 527
8 C 450
38 S 591 3 155 952
37 B 592 8 179 258
31 C 362
17 S 594 2 194 931
18 C 194
1 B 596 5 189 599
21 B 597 3 102 580
47 B 598 1 193 464
59 B 599 1 183 769
33 C 549
9 C 563
5 C 522
44 B 603 1 198 250
1 B 604 7 144 253
19 S 605 7 185 83
35 C 320
58 C 547
7 S 608 9 152 810
59 S 609 2 187 154
56 B 610 4 133 342
21 C 587
52 B 612 6 171 635
35 B 613 8 158 186
48 B 614 7 165 776
41 S 615 9 167 959
4 C 111
53 C 318
2 S 618 4 162 337
40 B 619 9 147 825
58 S 620 4 111 362
11 S 621 2 145 612
21 S 622 4 113 996
35 B 623 6 107 797
32 B 624 8 170 118
57 B 625 9 135 44
46 C 192
31 B 627 7 121 74
38 S 628 8 113 959
33 B 629 9 126 208
3 S 630 4 140 403
